Workbook
Name sec: 'บรรจุ'!$R$1:$R$220

Sheet บรรจุ
A1: ลำดับ | B1: ยศ | C1: ชื่อ | D1: สกุล | E1: fullname | F1: Rank | G1: Name | H1: Lastname | I1: หมายเลขประจำตัว | J1: หมายเลขประชาชน | K1: ตำแหน่งในสนาม | L1: ตำแหน่งปกติ | M1: ชั้นเงินเดือน | N1: กลุ่มเลือด | O1: หมายเหตุ | Q1: ยศปัจจุบันเมื่อ | R1: ส่วนงาน | S1: สังกัด | T1: รูปภาพ | U1: วัน เดือน ปี เกิด | V1: ศาสนา | W1: อายุ | X1: เพศ | Y1: ประเภท | Z1: ชื่อเล่น | AA1: Line ID | AB1: Email | AC1: ผู้บังคับบัญชา | AD1: PASSPORT | AE1: UN ID
A2: 1 | B2: พ.ท. | C2: วีระพงศ์ | D2: จันทรศิริภาส | E2: =B2&" "&C2&" "&D2 -> พ.ท. วีระพงศ์ จันทรศิริภาส | F2: LT COL | G2: Weerapong | H2: Jantarasiripas | I2: 1455601717 | J2: 1909900040261 | K2: ผู้บังคับกองร้อย | L2: ฝอ.3 พัน.ช.คมศ.พล.ช. | M2: น.3 ชั้น 26.5 (44130.-บาท) | N2: โอ | O2: กช. | P2: 898764145 | R2: กองบังคับการกองร้อย | T2: https://drive.google.com/file/d/1oW903yndbyjMo_d0LEBXyHTtelkcu7tS/view?usp=drivesdk | U2: 31021 | V2: พุทธ | W2: =DATEDIF(U2,TODAY(),"Y") -> 41 | X2: ชาย | Y2: สัญญาบัตร | Z2: เด่น | AA2: Zodiak. | AB2: dafil_45@hotmail.com | AD2: OF2059313 | AE2: PKF-THAI-01235
A3: 2 | B3: พ.ท. | C3: นฤเบศร์ | D3: บุญคุ้ม | E3: =B3&" "&C3&" "&D3 -> พ.ท. นฤเบศร์ บุญคุ้ม | F3: LT COL | G3: Narubase | H3: Boonkoom | I3: 1520802081 | J3: 1200100337887 | K3: รองผู้บังคับกองร้อย | L3: อจ.รร.ช.กช. | M3: น.2 ชั้น 22.5 (31340.-บาท) | N3: โอ | O3: กช. | P3: 957966251 | R3: กองบังคับการกองร้อย | T3: https://drive.google.com/file/d/1cm8_towT3j0qlQu7AUxw7f4f9z2iCcbe/view?usp=drivesdk | U3: 33296 | V3: พุทธ | W3: =DATEDIF(U3,TODAY(),"Y") -> 35 | X3: ชาย | Y3: สัญญาบัตร | Z3: สอง | AD3: OF2047842 | AE3: PKF-THAI-01236
A4: 3 | B4: ร.อ. | C4: พัฒนศักดิ์ | D4: บุญประเสริฐ | E4: =B4&" "&C4&" "&D4 -> ร.อ. พัฒนศักดิ์ บุญประเสริฐ | F4: CAPT | G4: Pattanasak | H4: Boonprasert | I4: 1494900475 | J4: 1700200038909 | K4: นายทหารฝ่ายกำลังพล | L4: ผช.นสบ.พล.ช. | M4: น.1 ชั้น 39 (30790.-บาท) | N4: โอ | O4: กช. | P4: 877540373 | R4: กองบังคับการกองร้อย | T4: https://drive.google.com/file/d/16DS_1Jq0KkRsta8FoJ4oWP7T5oMw_IPU/view?usp=drivesdk | U4: 32136 | V4: พุทธ | W4: =DATEDIF(U4,TODAY(),"Y") -> 38 | X4: ชาย | Y4: สัญญาบัตร | Z4: แก่ง | AA4: @jane8675 | AB4: pattanasak_1@hotmail.com | AD4: OF2059361 | AE4: PKF-THAI-01237
A5: 4 | B5: พ.ต. | C5: ครรชิต | D5: โสภาสาย | E5: =B5&" "&C5&" "&D5 -> พ.ต. ครรชิต โสภาสาย | F5: MAJ | G5: Khanchit | H5: Soparsai | I5: 1495000342 | J5: 1160100207402 | K5: นายทหารฝ่ายยุทธการและการข่าว | L5: อจ.รร.ช.กช. | M5: น.2 ชั้น 23.5 (32450.-บาท) | N5: บี | O5: กช. | P5: 910568849 | R5: กองบังคับการกองร้อย | T5: https://drive.google.com/file/d/15qPR93JxJdhVpkq7eXVUDMwIqU-BjtMS/view?usp=drivesdk | U5: 32159 | V5: พุทธ | W5: =DATEDIF(U5,TODAY(),"Y") -> 38 | X5: ชาย | Y5: สัญญาบัตร | Z5: เอ๋ | AD5: OF2000140 | AE5: PKF-THAI-01238
A6: 5 | B6: ร.อ. | C6: วีรวัฒน์ | D6: เลาอารีกิจ | E6: =B6&" "&C6&" "&D6 -> ร.อ. วีรวัฒน์ เลาอารีกิจ | F6: CAPT | G6: Weerawat | H6: Lao-areekit | I6: 1482800925 | J6: 1311100021782 | K6: นายทหารฝ่ายส่งกำลังบำรุง | L6: ประจำแผนก กคช.กช. | M6: น.1 ชั้น 38 (29680.-บาท) | N6: เอ | O6: กช. | P6: 871669123 | R6: กองบังคับการกองร้อย | T6: https://drive.google.com/file/d/1IWny1kcxmjykdWtQLC4ioR8iPexn88R3/view?usp=drivesdk | U6: 30690 | V6: พุทธ | W6: =DATEDIF(U6,TODAY(),"Y") -> 42 | X6: ชาย | Y6: สัญญาบัตร | Z6: อ๋อง | AA6: sgt.weerawat_aong | AB6: aongsky@gmail.com | AD6: OF2059874 | AE6: PKF-THAI-01239
A7: 6 | B7: ร.ท.หญิง | C7: ทิพวรรณ | D7: บุญหวา | E7: =B7&" "&C7&" "&D7 -> ร.ท.หญิง ทิพวรรณ บุญหวา | F7: 1LT | G7: Tippawan | H7: Boonwha | I7: 6491050500 | J7: 1640500026036 | K7: นายทหารฝ่ายการเงิน | L7: ประจำแผนกเงินเดือน กงด.กง.ทหาร | M7: น.1 38.5 (30220.-บาท) | N7: โอ | O7: บก.ทท. | P7: 850397199 | R7: กองบังคับการกองร้อย | T7: https://drive.google.com/file/d/13Ac_41z86j4UZAZWrJt6vsO64Y9ZbRuD/view?usp=drivesdk | U7: 31417 | V7: พุทธ | W7: =DATEDIF(U7,TODAY(),"Y") -> 40 | X7: หญิง | Y7: สัญญาบัตร | Z7: หยุย | AA7: miyuki.yuii | AB7: tippawan.bo@rtarf.mi.th | AD7: OF2059415 | AE7: PKF-THAI-01240
A8: 7 | B8: ร.อ. | C8: พัฐสรร | D8: อินนุช | E8: =B8&" "&C8&" "&D8 -> ร.อ. พัฐสรร อินนุช | F8: CAPT | G8: Patsun | H8: Innuch | I8: 1362402118 | J8: 3120100197233 | K8: นายทหารพระธรรมนูญ | L8: ประจำแผนกบังคับคดี กคด.สธน.ทบ. | M8: น.1 ชั้น 44.5 (36990.-บาท) | N8: เอบี | O8: สธน.ทบ. | P8: 923655688 | R8: กองบังคับการกองร้อย | T8: https://drive.google.com/file/d/17PU3oxIQ2Qa9GisC58jyCE5Km-uqo3Cx/view?usp=drivesdk | U8: 27498 | V8: พุทธ | W8: =DATEDIF(U8,TODAY(),"Y") -> 51 | X8: ชาย | Y8: สัญญาบัตร | Z8: โต้ง | AA8: tonic5688 | AB8: patsun1975@gmail.com | AD8: OF2059279 | AE8: PKF-THAI-01241
A9: 8 | B9: พ.ต. | C9: คนอง | D9: คำปิว | E9: =B9&" "&C9&" "&D9 -> พ.ต. คนอง คำปิว | F9: MAJ | G9: Kanong | H9: Kampiew | I9: 1554100056 | J9: 1540300009163 | K9: อนุศาสนาจารย์ | L9: อศจ.รร.นส.ทบ. | M9: น.2 ชั้น 23.5 (32450.-บาท) | N9: บี | O9: ยศ.ทบ. | P9: 612935391 | R9: กองบังคับการกองร้อย | T9: https://drive.google.com/file/d/1LNMkgj_QgnuJwl-zuvK8oOG97nPUL0vO/view?usp=drivesdk | U9: 31058 | V9: พุทธ | W9: =DATEDIF(U9,TODAY(),"Y") -> 41 | X9: ชาย | Y9: สัญญาบัตร | Z9: นอง | AA9: Kanongtb1 | AB9: kanongtb1@gmail.com | AD9: OF2059309 | AE9: PKF-THAI-01242
A10: 9 | B10: พ.ท. | C10: ปรัชฌา | D10: อุบลรัตน์ | E10: =B10&" "&C10&" "&D10 -> พ.ท. ปรัชฌา อุบลรัตน์ | F10: LT COL | G10: Pratcha | H10: U-bolrat | I10: 1494901694 | J10: 1709900371340 | K10: นายทหารประสานงาน | L10: ประจำแผนก ยก.ทบ. | M10: น.3 ชั้น 22.5 (38500.-บาท) | N10: โอ | O10: ยก.ทบ. | P10: 954484960 | R10: กองบังคับการกองร้อย | T10: https://drive.google.com/file/d/1hW_TWr2vbOsIzr8-za1XObxpCNhccvI-/view?usp=drivesdk | U10: 32285 | V10: พุทธ | W10: =DATEDIF(U10,TODAY(),"Y") -> 38 | X10: ชาย | Y10: สัญญาบัตร | Z10: บิ่น | AD10: OF2031194 | AE10: PKF-THAI-01243
A11: 10 | B11: พ.ท. | C11: วิทยา | D11: ชารีรัตน์ | E11: =B11&" "&C11&" "&D11 -> พ.ท. วิทยา ชารีรัตน์ | F11: LT COL | G11: Wittaya | H11: Chareerut | I11: 1467700472 | J11: 1341800011216 | K11: นายทหารประสานงาน | L11: หน.กบ.ทบ. | M11: น.3 ชั้น 24.5 (41250.-บาท) | N11: โอ | O11: กบ.ทบ. | P11: 927446169 | R11: กองบังคับการกองร้อย | T11: https://drive.google.com/file/d/1lubT0KTTqniDhG6dgb2LN_OxRhCfwQlT/view?usp=drivesdk | U11: 31042 | V11: พุทธ | W11: =DATEDIF(U11,TODAY(),"Y") -> 41 | X11: ชาย | Y11: สัญญาบัตร | Z11: ต้น | AD11: OF2008894 | AE11: PKF-THAI-01244
A12: 11 | B12: พ.ต. | C12: อธิราช | D12: สีสุกงาม | E12: =B12&" "&C12&" "&D12 -> พ.ต. อธิราช สีสุกงาม | F12: MAJ | G12: Atirach | H12: Seesugngam | I12: 1432901022 | J12: 3100502031283 | K12: นายทหารประสานงาน | L12: ประจำแผนก ยก.ทบ. | M12: น.1 ชั้น 36.5 (28430.-บาท) | N12: บี | O12: ยก.ทบ. | P12: 818068599 | R12: กองบังคับการกองร้อย | T12: https://drive.google.com/file/d/1CIeMjBjkXsCZGnEBelhSLO_SCs4PWTDl/view?usp=drivesdk | U12: 30063 | V12: พุทธ | W12: =DATEDIF(U12,TODAY(),"Y") -> 44 | X12: ชาย | Y12: สัญญาบัตร | Z12: กอล์ฟ | AA12: NIRVANA | AB12: aseesugngam@gmail.com | AD12: OF2059305 | AE12: PKF-THAI-01099
A13: 12 | B13: ร.อ.หญิง | C13: เกวลี | D13: เพ็ชรแก้ว | E13: =B13&" "&C13&" "&D13 -> ร.อ.หญิง เกวลี เพ็ชรแก้ว | F13: CAPT | G13: Kewalee | H13: Phetkaew | I13: 6611050024 | J13: 1101700062902 | K13: นายทหารประสานงาน | L13: ประจำแผนกปฏิบัติการ กปก.ศสภ.ยก.ทหาร | M13: น.1 29 (22600.-บาท) | N13: โอ | O13: บก.ทท. | P13: 989922632 | R13: กองบังคับการกองร้อย | T13: https://drive.google.com/file/d/17GoBlGLZLwr-NAG3dvXyyHNvklbh6QHX/view?usp=drivesdk | U13: 31911 | V13: พุทธ | W13: =DATEDIF(U13,TODAY(),"Y") -> 39 | X13: หญิง | Y13: สัญญาบัตร | Z13: กิฟท์ | AA13: wumingting | AB13: kewalee.p777@gmail.com | AD13: OF2059784 | AE13: PKF-THAI-01245
A14: 13 | B14: น.ต.หญิง | C14: เมทิกา | D14: วงษ์ฤทธิ์ | E14: =B14&" "&C14&" "&D14 -> น.ต.หญิง เมทิกา วงษ์ฤทธิ์ | F14: SQN LDR | G14: Maytika | H14: Wongrid | I14: 8571030410 | J14: 1101400644761 | K14: นายทหารประสานงาน | L14: นายทหารวิเคราะห์งบประมาณ สปช.ทหาร | M14: น.2 20.5 (29110.-บาท) | N14: เอ | O14: บก.ทท. | P14: 952432645 | R14: กองบังคับการกองร้อย | T14: https://drive.google.com/file/d/1iTdF1glELQ_kejotGx_RxPLDTLSRjTGR/view?usp=drivesdk | U14: 31360 | V14: พุทธ | W14: =DATEDIF(U14,TODAY(),"Y") -> 40 | X14: หญิง | Y14: สัญญาบัตร | Z14: กิ๊บ | AA14: nooogipzzy | AB14: maytika.w@rtarf.mi.th | AD14: OF2059417 | AE14: PKF-THAI-01246
A15: 14 | B15: ร.อ.หญิง | C15: กฤตยา | D15: แก้วเรียน | E15: =B15&" "&C15&" "&D15 -> ร.อ.หญิง กฤตยา แก้วเรียน | F15: CAPT | G15: Krittaya | H15: Kaewrian | I15: 6611051320 | J15: 1103701441259 | K15: นายทหารประสานงาน | L15: ประจำ ผยก.กยก.นทพ. | M15: น.1 29 (22600.-บาท) | N15: โอ | O15: บก.ทท. | P15: 819797451 | R15: กองบังคับการกองร้อย | T15: https://drive.google.com/file/d/1-BvJzfTaNScYNreRsDTPN201kPj1wqsm/view?usp=drivesdk | U15: 34563 | V15: พุทธ | W15: =DATEDIF(U15,TODAY(),"Y") -> 32 | X15: หญิง | Y15: สัญญาบัตร | Z15: ไอ๊ซ์ซึ | AA15: icekaewrian | AB15: icekaewrian@gmail.com | AD15: OF2059765 | AE15: PKF-THAI-01247
A16: 15 | B16: จ.ส.อ. | C16: สุเทพ | D16: พะเวก | E16: =B16&" "&C16&" "&D16 -> จ.ส.อ. สุเทพ พะเวก | F16: SM1 | G16: Sutep | H16: Pavek | I16: 1384900323 | J16: 3700700346200 | K16: จ่ากองร้อย | L16: จ่ากองร้อย บก.ร้อย.ร้อย.บก.ช.11 | M16: ป.3 ชั้น 36.5 (38170.-บาท) | N16: โอ | O16: กช. | P16: 859333922 | R16: กองบังคับการกองร้อย | T16: https://drive.google.com/file/d/1a6sQZh2d2iJnKiQvUdTTD1usIXATg0ki/view?usp=drivesdk | U16: 27817 | V16: พุทธ | W16: =DATEDIF(U16,TODAY(),"Y") -> 50 | X16: ชาย | Y16: ประทวน | Z16: ฮอลล์ | AA16: 08593339222 | AB16: Pavek27_@hotmail.com | AD16: OF2059338 | AE16: PKF-THAI-01248
A17: 16 | B17: จ.ส.อ. | C17: ชัยภัทร | D17: ทำทวี | E17: =B17&" "&C17&" "&D17 -> จ.ส.อ. ชัยภัทร ทำทวี | F17: SM1 | G17: Chaiyaphat | H17: Tamtavee | I17: 1522801609 | J17: 1310400120475 | K17: เสมียนกองร้อย/พลประจำ รยบ.ขนาดเบา 4x4 แบบ 51B | L17: นายสิบกำลังพล ร้อย.บก.ช.11 | M17: ป.2 ชั้น 28 (20950.-บาท) | N17: บี | O17: กช. | P17: 0622267585 | R17: กองบังคับการกองร้อย | T17: https://drive.google.com/file/d/1q-XOz5JIWCny948j8Qihlj9J6FiuFwRB/view?usp=drivesdk | U17: 32173 | V17: พุทธ | W17: =DATEDIF(U17,TODAY(),"Y") -> 38 | X17: ชาย | Y17: ประทวน | Z17: สา | AA17: sa310131 | AB17: chaiyaphat2531sa@gmail.com | AD17: OF2059323 | AE17: PKF-THAI-01249
A18: 17 | B18: ส.ต.หญิง | C18: นรารัตน์ | D18: พวงนวม | E18: =B18&" "&C18&" "&D18 -> ส.ต.หญิง นรารัตน์ พวงนวม | F18: PFC | G18: Nararat | H18: Puangnuam | I18: 6661011454 | J18: 2709900020201 | K18: นายสิบกำลังพล | L18: เสมียน กชฝ.กช. | M18: ป.1 ชั้น 16 (9520.-บาท) | N18: บี | O18: กช. | P18: 634968549 | R18: กองบังคับการกองร้อย | T18: https://drive.google.com/file/d/11nREyXEcQzcaE5ymQN6_ro5_yTV1fBmQ/view?usp=drivesdk | U18: 33379 | V18: พุทธ | W18: =DATEDIF(U18,TODAY(),"Y") -> 35 | X18: หญิง | Y18: ประทวน | Z18: อีฟ | AA18: eiiviie | AB18: nararat.pn@gmail.com | AD18: OF2059329 | AE18: PKF-THAI-01100
A19: 18 | B19: จ.ส.อ. | C19: ศักดิ์ดา | D19: วลัยศรี | E19: =B19&" "&C19&" "&D19 -> จ.ส.อ. ศักดิ์ดา วลัยศรี | F19: SM1 | G19: Sakda | H19: Walaisri | I19: 1530300474 | J19: 1460500137158 | K19: นายสิบการข่าว/พลประจำ รยบ.ขนาดเบา 4x4 แบบ 51B | L19: นายสิบธุรการ ฝกพ.พล.ช. | M19: ป.2 ชั้น 28 (20950.-บาท) | N19: เอบี | O19: กช. | P19: 831551644 | R19: กองบังคับการกองร้อย | T19: https://drive.google.com/file/d/1DolbM2EDkg24KRa01lYAEpD706RGd8AA/view?usp=drivesdk | U19: 32719 | V19: พุทธ | W19: =DATEDIF(U19,TODAY(),"Y") -> 37 | X19: ชาย | Y19: ประทวน | Z19: ณะ | AA19: dawalai1989 | AB19: dawalai1989@gmail.com | AD19: OF2059324 | AE19: PKF-THAI-01250
A20: 19 | B20: ส.อ. | C20: ธีรัช | D20: วันดี | E20: =B20&" "&C20&" "&D20 -> ส.อ. ธีรัช วันดี | F20: SGT | G20: Thirath | H20: Wandee | I20: 1603300739 | J20: 1100702368188 | K20: นายสิบยุทธการ | L20: เสมียนพิมพ์ดีด ฝขว.พล.ช. | M20: ป.1 ชั้น 27 (14560.-บาท) | N20: โอ | O20: กช. | P20: 956199036 | R20: กองบังคับการกองร้อย | T20: https://drive.google.com/file/d/1eC6u9A51mWwoRPXEBSg8l4lTF62-o1el/view?usp=drivesdk | U20: 35290 | V20: พุทธ | W20: =DATEDIF(U20,TODAY(),"Y") -> 30 | X20: ชาย | Y20: ประทวน | Z20: เนม | AD20: OF2059275 | AE20: PKF-THAI-01251
A21: 20 | B21: จ.ส.อ. | C21: ฐิติวุฒิ | D21: ถมยา | E21: =B21&" "&C21&" "&D21 -> จ.ส.อ. ฐิติวุฒิ ถมยา | F21: SM1 | G21: Thitiwut | H21: Tomya | I21: 1353900699 | J21: 3760500363879 | K21: ผู้ช่วยนายสิบยุทธการ/พลประจำ รยบ.ขนาดเบา 4x4 แบบ 51B | L21: เสมียน กยข.กช. | M21: ป.3 ชั้น 34.5 (35810.-บาท) | N21: บี | O21: กช. | P21: 996825143 | R21: กองบังคับการกองร้อย | T21: https://drive.google.com/file/d/1lhjlj1c485lSYyY5R5Qe7bdEGKYEZfTs/view?usp=drivesdk | U21: 26919 | V21: พุทธ | W21: =DATEDIF(U21,TODAY(),"Y") -> 53 | X21: ชาย | Y21: ประทวน | Z21: ต้อม (ย้อย) | AA21: YOY2737 | AB21: thitiwut2737@gmail.com | AD21: OF2059343 | AE21: PKF-THAI-01252
A22: 21 | B22: ส.อ.หญิง | C22: ญาณกร | D22: สุรารักษ์ | E22: =B22&" "&C22&" "&D22 -> ส.อ.หญิง ญาณกร สุรารักษ์ | F22: SGT | G22: Yanakorn | H22: Surarak | I22: 6601011451 | J22: 1709900887133 | K22: นายสิบส่งกำลังบำรุง | L22: เสมียน กคช.กช. | M22: ป.1 ชั้น 27.5 (14810.-บาท) | N22: โอ | O22: กช. | P22: 656380699 | R22: กองบังคับการกองร้อย | T22: https://drive.google.com/file/d/1moTJnpcvPohVSueg2tu1TIng5Rpjtb-I/view?usp=drivesdk | U22: 34480 | V22: พุทธ | W22: =DATEDIF(U22,TODAY(),"Y") -> 32 | X22: หญิง | Y22: ประทวน | Z22: มุก | AA22: mookmik26 | AB22: mookmikza36@gmail.com | AD22: OF2059340 | AE22: PKF-THAI-01101
A23: 22 | B23: ส.อ. | C23: จิรวัฒน์ | D23: แตงจั่น | E23: =B23&" "&C23&" "&D23 -> ส.อ. จิรวัฒน์ แตงจั่น | F23: SGT | G23: Jirawat | H23: Taengjun | I23: 1611900023 | J23: 1739901860239 | K23: ผู้ช่วยนายสิบส่งกำลังบำรุง/พลประจำ รยบ.ขนาดเบา 4x4 แบบ 51B | L23: เสมียน กกบ.กช. | M23: ป.1 ชั้น 26.5 (14320.-บาท) | N23: บี | O23: กช. | P23: 823618989 | R23: กองบังคับการกองร้อย | T23: https://drive.google.com/file/d/1SkNaWNMQDzfVATQvHoAN0m3h1IZl9kWj/view?usp=drivesdk | U23: 36508 | V23: พุทธ | W23: =DATEDIF(U23,TODAY(),"Y") -> 26 | X23: ชาย | Y23: ประทวน | Z23: เต้ | AA23: taecom14 | AB23: jirawattae35@gmail.com | AD23: OF2059342 | AE23: PKF-THAI-01253
A24: 23 | B24: ส.ท.หญิง | C24: วรวรรณ | D24: ฐานะ | E24: =B24&" "&C24&" "&D24 -> ส.ท.หญิง วรวรรณ ฐานะ | F24: CPL | G24: Worawan | H24: Thana | I24: 6621011452 | J24: 1459900553751 | K24: ผู้ช่วยนายสิบส่งกำลังบำรุง | L24: เสมียน กคช.กช. | M24: ป.1 ชั้น 23.5 (12810.-บาท) | N24: โอ | O24: กช. | P24: 971758084 | R24: กองบังคับการกองร้อย | T24: https://drive.google.com/file/d/1xMJxCMusvPJttNEw87lVYs6mlbCRRc_w/view?usp=drivesdk | U24: 35219 | V24: พุทธ | W24: =DATEDIF(U24,TODAY(),"Y") -> 30 | X24: หญิง | Y24: ประทวน | Z24: เปรี้ยว | AA24: @worawan555 | AB24: pauw.mini@gmail.com | AD24: OF2059344 | AE24: PKF-THAI-01102
A25: 24 | B25: ส.ต.หญิง | C25: ณิชากร | D25: ล้ำสุขดี | E25: =B25&" "&C25&" "&D25 -> ส.ต.หญิง ณิชากร ล้ำสุขดี | F25: PFC | G25: Nichakorn | H25: Lamsukdee | I25: 6661011452 | J25: 1300201239677 | K25: นายสิบกิจการพลเรือน | L25: เสมียน กยข.กช. | M25: ป.1 ชั้น 15.5 (9330.-บาท) | N25: เอ | O25: กช. | P25: 971433535 | R25: กองบังคับการกองร้อย | T25: https://drive.google.com/file/d/157ZfdxI1mpvgX2QNkDC4TXSY-bQB6-jZ/view?usp=drivesdk | U25: 36360 | V25: พุทธ | W25: =DATEDIF(U25,TODAY(),"Y") -> 27 | X25: หญิง | Y25: ประทวน | Z25: อันดา | AA25: andanichakon | AB25: nichakornlamsukdee@gmail.com | AD25: OF2059334 | AE25: PKF-THAI-01103
A26: 25 | B26: ส.อ.หญิง | C26: ณิชา | D26: โพธิเงิน | E26: =B26&" "&C26&" "&D26 -> ส.อ.หญิง ณิชา โพธิเงิน | F26: SGT | G26: Nicha | H26: Phongern | I26: 6611010496 | J26: 1709901260673 | K26: นายสิบการเงิน | L26: เสมียนการเงินและการบัญชี ผกง.กช. | M26: ป.1 ชั้น 25.5 (13820.-บาท) | N26: บี | O26: กช. | P26: 625742139 | R26: กองบังคับการกองร้อย | T26: https://drive.google.com/file/d/1UZP49VkAdO8yrwQdgFpqNd7quU8fnTRP/view?usp=drivesdk | U26: 36259 | V26: พุทธ | W26: =DATEDIF(U26,TODAY(),"Y") -> 27 | X26: หญิง | Y26: ประทวน | Z26: บี | AA26: beebee0904 | AB26: beebeenicha9@gmail.com | AD26: OF2025505 | AE26: PKF-THAI-01104
A27: 26 | B27: ส.อ. | C27: อัครพงศ์ | D27: ศิลปกิจ | E27: =B27&" "&C27&" "&D27 -> ส.อ. อัครพงศ์ ศิลปกิจ | F27: SGT | G27: Arkarapong | H27: Sinrapagit | I27: 1604900079 | J27: 1730600149988 | K27: นายสิบสื่อโสตทัศน์ และสื่อวิดีทัศน์ | L27: ช่างภาพ กกร.กช. | M27: ป.1 ชั้น 25.5 (13820.-บาท) | N27: เอบี | O27: กช. | P27: 645617274 | R27: กองบังคับการกองร้อย | T27: https://drive.google.com/file/d/1Rss1c_7-5622o2SfwOvX6LN0Rj0j_AWZ/view?usp=drivesdk | U27: 35200 | V27: พุทธ | W27: =DATEDIF(U27,TODAY(),"Y") -> 30 | X27: ชาย | Y27: ประทวน | Z27: เบนซ์ | AA27: Benz9941 | AB27: foxsilverclass@gmail.com | AD27: OF2059317 | AE27: PKF-THAI-01254
A28: 27 | B28: ส.ต.หญิง | C28: ณัฐกมล | D28: มงคล | E28: =B28&" "&C28&" "&D28 -> ส.ต.หญิง ณัฐกมล มงคล | F28: PFC | G28: Nattakamon | H28: Mongkon | I28: 6661011453 | J28: 1930200085085 | K28: นายสิบสื่อโสตทัศน์ และสื่อวิดีทัศน์ | L28: เสมียน ผธก.กช. | M28: ป.1 ชั้น 15.5 (9330.-บาท) | N28: เอ | O28: กช. | P28: 863600223 | R28: กองบังคับการกองร้อย | T28: https://drive.google.com/file/d/1Rli-QK-c9-mVCmp5LNboExLKn_IVYY2_/view?usp=drivesdk | U28: 35440 | V28: อิสลาม | W28: =DATEDIF(U28,TODAY(),"Y") -> 29 | X28: หญิง | Y28: ประทวน | Z28: กวาง | AA28: kwang-s125 | AB28: kwang.mongkon10@gmail.com | AD28: OF2059331 | AE28: PKF-THAI-01105
A29: 28 | B29: ส.อ.หญิง | C29: เบญจมาส | D29: มหาชัย | E29: =B29&" "&C29&" "&D29 -> ส.อ.หญิง เบญจมาส มหาชัย | F29: SGT | G29: Benjamas | H29: Mahachai | I29: 6591013547 | J29: 1169800094005 | K29: นายสิบประสานงาน | L29: เสมียน แผนกวิชาการและห้องสมุด กฝศ.ศสภ.ยก.ทหาร | M29: ป.1 28 (15060.-บาท) | N29: เอ | O29: บก.ทท. | P29: 646615596 | R29: กองบังคับการกองร้อย | T29: https://drive.google.com/file/d/1_GT9xjvzkwoWYMFXNl9gum2IYNcL1QLZ/view?usp=drivesdk | U29: 32688 | V29: พุทธ | W29: =DATEDIF(U29,TODAY(),"Y") -> 37 | X29: หญิง | Y29: ประทวน | Z29: ติ๋ว | AA29: - | AB29: benjamas.m@rtarf.mi.th | AD29: OF2023804 | AE29: PKF-THAI-01255
A30: 29 | B30: ส.อ.หญิง | C30: อรพรรณ | D30: ทัพชัย | E30: =B30&" "&C30&" "&D30 -> ส.อ.หญิง อรพรรณ ทัพชัย | F30: SGT | G30: Orapan | H30: Thupchai | I30: 6591010207 | J30: 1101800203362 | K30: นายสิบประสานงาน | L30: เสมียน ยก.ทบ. | M30: ป.1 ชั้น 28 (15060.-บาท) | N30: โอ | O30: ยก.ทบ. | P30: 629569455 | R30: กองบังคับการกองร้อย | T30: https://drive.google.com/file/d/1kW4Ym_bqReizVSubZvHJRYQKnrOmXLRD/view?usp=drivesdk | U30: 31679 | V30: พุทธ | W30: =DATEDIF(U30,TODAY(),"Y") -> 40 | X30: หญิง | Y30: ประทวน | Z30: บี | AA30: bbcoolgirl | AB30: orapancool@outlook.com | AD30: OF2059760 | AE30: PKF-THAI-01256
A31: 30 | B31: จ.ส.ต. | C31: พิภพ | D31: หนูผาสุข | E31: =B31&" "&C31&" "&D31 -> จ.ส.ต. พิภพ หนูผาสุข | F31: SM3 | G31: Pipob | H31: Noophasuk | I31: 1554900518 | J31: 1709900853298 | K31: พลขับรถ รยบ.4x4 ฟอร์จูนเนอร์ | L31: เสมียนกองร้อย บก.ร้อย.ร้อย.บก.พัน.ช.คมศ.พล.ช. | M31: ป.2 ชั้น 28 (20950.-บาท) | N31: เอ | O31: กช. | P31: 649616294 | R31: กองบังคับการกองร้อย | T31: https://drive.google.com/file/d/1fyWDUyZEhX-Yve47sNLRLPDYCQzF6Ee-/view?usp=drivesdk | U31: 34325 | V31: พุทธ | W31: =DATEDIF(U31,TODAY(),"Y") -> 32 | X31: ชาย | Y31: ประทวน | Z31: โอ๊ต | AA31: 1709900853298 | AB31: love_pipob@hotmail.com | AD31: OF2059318 | AE31: PKF-THAI-01106
A32: 31 | B32: ร.ท. | C32: จิรายุทธ | D32: แก้วยอด | E32: =B32&" "&C32&" "&D32 -> ร.ท. จิรายุทธ แก้วยอด | F32: 1LT | G32: Jirayut | H32: Kaewyod | I32: 1594902216 | J32: 1709901184721 | K32: ผู้บังคับหมวด | L32: ผบ.มว.งานดิน ร้อย.ช.ก่อสร้าง ช.11 พัน.111 | M32: น.1 ชั้น 28.5 (22230.-บาท) | N32: เอ | O32: กช. | P32: 955396359 | R32: หมวดก่อสร้างทางระดับที่ 1 | T32: https://drive.google.com/file/d/1xlwpyq3S4v3QfjRViU6gcW9wm5WJpXSk/view?usp=drivesdk | U32: 35805 | V32: พุทธ | W32: =DATEDIF(U32,TODAY(),"Y") -> 28 | X32: ชาย | Y32: สัญญาบัตร | Z32: เบส | AD32: OF2059281 | AE32: PKF-THAI-01257
A33: 32 | B33: จ.ส.อ. | C33: นุกูล | D33: ปิ่นแก้ว | E33: =B33&" "&C33&" "&D33 -> จ.ส.อ. นุกูล ปิ่นแก้ว | F33: SM1 | G33: Nukool | H33: Pinkaew | I33: 1373309575 | J33: 3100203113776 | K33: รองผู้บังคับหมวด | L33: นายงานเครื่องมือก่อสร้าง ช.11 พัน.111 | M33: ป.3 ชั้น 36 (37580.-บาท) | N33: โอ | O33: กช. | P33: 800146550 | R33: หมวดก่อสร้างทางระดับที่ 1 | T33: https://drive.google.com/file/d/1StTKFLPPjjHWjowf1Yk_N9Y_Rv7n6uji/view?usp=drivesdk | U33: 27488 | V33: พุทธ | W33: =DATEDIF(U33,TODAY(),"Y") -> 51 | X33: ชาย | Y33: ประทวน | Z33: กุล | AA33: 0800146550 | AB33: nukoolpinkeaw@gmail.com | AD33: OF2059319 | AE33: PKF-THAI-01107
A34: 33 | B34: จ.ส.อ. | C34: สุวิทย์ | D34: ชัยโย | E34: =B34&" "&C34&" "&D34 -> จ.ส.อ. สุวิทย์ ชัยโย | F34: SM1 | G34: Suwit | H34: Chaiyo | I34: 1464900581 | J34: 1700790002762 | K34: นายสิบประจำหมวด/พลวิทยุ | L34: ครูผู้ช่วย รร.ช.กช. | M34: ป.3 ชั้น 29 (29680.-บาท) | N34: เอบี | O34: กช. | P34: 838313881 | R34: หมวดก่อสร้างทางระดับที่ 1 | T34: https://drive.google.com/file/d/1Ii1bfFTOVSjX_0_FxzeR8obbeKgW6qEg/view?usp=drivesdk | U34: 31288 | V34: พุทธ | W34: =DATEDIF(U34,TODAY(),"Y") -> 41 | X34: ชาย | Y34: ประทวน | Z34: บอล | AA34: Ballchaiyo | AB34: ballchaiyo@gmail.com | AD34: OF2059337 | AE34: PKF-THAI-01108
A35: 34 | B35: ส.อ. | C35: ภูมิพัฒน์ | D35: สว่างแจ้ง | E35: =B35&" "&C35&" "&D35 -> ส.อ. ภูมิพัฒน์ สว่างแจ้ง | F35: SGT | G35: Phumiphat | H35: Sawangchaeng | I35: 1626000001 | J35: 1759900368659 | K35: ช่างสำรวจ | L35: ช่างอาวุธ ช.11 พัน.111 | M35: ป.1 ชั้น 26.5 (14320.-บาท) | N35: โอ | O35: กช. | P35: 926603184 | R35: หมวดก่อสร้างทางระดับที่ 1 | T35: https://drive.google.com/file/d/1HqkMVxKdpyHpFUofUvS4ln7Qs5uHNq_F/view?usp=drivesdk | U35: 36656 | V35: พุทธ | W35: =DATEDIF(U35,TODAY(),"Y") -> 26 | X35: ชาย | Y35: ประทวน | Z35: ฟิวส์ | AA35: ffew. | AB35: poomphat2261@gmail.com | AD35: OF2059761 | AE35: PKF-THAI-01258
A36: 35 | B36: จ.ส.อ. | C36: ณัฐพล | D36: นาคอ่อน | E36: =B36&" "&C36&" "&D36 -> จ.ส.อ. ณัฐพล นาคอ่อน | F36: SM1 | G36: Nattapon | H36: Nakoon | I36: 1564900381 | J36: 1709900907061 | K36: ช่างสำรวจ | L36: พลขับ พัน.ช.กช.ร้อย.1 | M36: ป.2 ชั้น 26 (19720.-บาท) | N36: โอ | O36: กช. | P36: 655681686 | R36: หมวดก่อสร้างทางระดับที่ 1 | T36: https://drive.google.com/file/d/18_U0i-vjn4b_awJb6PSw_c93NdBlb-7f/view?usp=drivesdk | U36: 34568 | V36: พุทธ | W36: =DATEDIF(U36,TODAY(),"Y") -> 32 | X36: ชาย | Y36: ประทวน | Z36: ไนท์ (night) | AA36: nightkn | AB36: nutty2j@gmail.com | AD36: OF2059336 | AE36: PKF-THAI-01109
A37: 36 | B37: จ.ส.อ. | C37: ธวัชชัย | D37: โพธิ์ศรีขาม | E37: =B37&" "&C37&" "&D37 -> จ.ส.อ. ธวัชชัย โพธิ์ศรีขาม | F37: SM1 | G37: Tawatchai | H37: Phosrikham | I37: 1530302475 | J37: 1460400042261 | K37: ผู้บังคับหมู่ | L37: พลประจำรถถากถาง ช.11 พัน.111 | M37: ป.2 ชั้น 31 (22790.-บาท) | N37: บี | O37: กช. | P37: 847972068 | R37: หมวดก่อสร้างทางระดับที่ 1 | T37: https://drive.google.com/file/d/1s4SdJoXbvQ0SlNIvd6Tswjc2AHEXu4zF/view?usp=drivesdk | U37: 33301 | V37: พุทธ | W37: =DATEDIF(U37,TODAY(),"Y") -> 35 | X37: ชาย | Y37: ประทวน | Z37: ตูม | AA37: toomnco1453 | AB37: toomlove1453@gmail.com | AD37: OF2059356 | AE37: PKF-THAI-01110
A38: 37 | B38: จ.ส.อ. | C38: วิบูลย์ | D38: ศรสุวรรณ | E38: =B38&" "&C38&" "&D38 -> จ.ส.อ. วิบูลย์ ศรสุวรรณ | F38: SM1 | G38: Viboon | H38: Sornsuwan | I38: 1565900241 | J38: 1709900981431 | K38: พลประจำรถถากถางขนาดเบา | L38: พลประจำรถถากถาง ช.11 พัน.111 | M38: ป.2 ชั้น 27 (20330.-บาท) | N38: บี | O38: กช. | P38: 952754853 | R38: หมวดก่อสร้างทางระดับที่ 1 | T38: https://drive.google.com/file/d/1yk-mer1Fq6asuK3IsnxWW116A1GfMZTp/view?usp=drivesdk | U38: 34892 | V38: พุทธ | W38: =DATEDIF(U38,TODAY(),"Y") -> 31 | X38: ชาย | Y38: ประทวน | Z38: เต้ | AA38: 0952754853 | AB38: 12viboon@gmail.com | AD38: OF2059284 | AE38: PKF-THAI-01259
A39: 38 | B39: จ.ส.อ. | C39: มานะพงษ์ | D39: จันทาอ่อน | E39: =B39&" "&C39&" "&D39 -> จ.ส.อ. มานะพงษ์ จันทาอ่อน | F39: SM1 | G39: Manapong | H39: Chan-ta-on | I39: 1424301988 | J39: 5440700004812 | K39: พลประจำรถโกยตักล้อยาง ขนาด 1 ลบ.ม. | L39: ช่างไฟฟ้า ช.11 พัน.111 | M39: ป.2 ชั้น 40+ย.1 (30790.-บาท) | N39: บี | O39: กช. | P39: 805395874 | R39: หมวดก่อสร้างทางระดับที่ 1 | T39: https://drive.google.com/file/d/1p-6AhpBj7ktAGm2ofk4Xbm14TmvE5EYB/view?usp=drivesdk | U39: 29471 | V39: พุทธ | W39: =DATEDIF(U39,TODAY(),"Y") -> 46 | X39: ชาย | Y39: ประทวน | Z39: ปุ๊ | AA39: purastathailand | AB39: freezer198052@gmail.com | AD39: OF2059759 | AE39: PKF-THAI-01111
A40: 39 | B40: จ.ส.อ. | C40: พิทยา | D40: บุญทา | E40: =B40&" "&C40&" "&D40 -> จ.ส.อ. พิทยา บุญทา | F40: SM1 | G40: Pittaya | H40: Bunta | I40: 1564603626 | J40: 1450400144551 | K40: พลประจำรถเกลี่ย | L40: พลขับรถบรรทุกหนัก ช.11 พัน.111 | M40: ป.2 ชั้น 28.5 (21250.-บาท) | N40: บี | O40: กช. | P40: 889998780 | R40: หมวดก่อสร้างทางระดับที่ 1 | T40: https://drive.google.com/file/d/1wA35U5egAvL_bCvgu2SY9gQs7AgaCf9-/view?usp=drivesdk | U40: 34383 | V40: พุทธ | W40: =DATEDIF(U40,TODAY(),"Y") -> 32 | X40: ชาย | Y40: ประทวน | Z40: ตั้ม | AA40: tumpittaya11111 | AB40: pittayabunta11111@gmail.com | AD40: OF2059756 | AE40: PKF-THAI-01112
...

Sheet นายทหาร
C1: ลำดับ | D1: ยศ – ชื่อ,นามสกุล | G1: fullname | H1: THAI-US ARMY RANKS | K1: หมายเลขประจำตัว | L1: หมายเลขประชาชน | M1: ตำแหน่งในสนาม | N1: ตำแหน่งปกติ | O1: ชั้นเงินเดือน | P1: กลุ่มเลือด | Q1: หมายเหตุ | S1: ยศปัจจุบันเมื่อ | T1: ส่วนงาน | U1: สังกัด | V1: รูปภาพ | W1: วัน เดือน ปี เกิด
A2: 1 | B2: 1 | C2: 1 | D2: พ.ท. | E2: วีระพงศ์ | F2: จันทรศิริภาส | G2: =D2&" "&E2&" "&F2 -> พ.ท. วีระพงศ์ จันทรศิริภาส | H2: LT COL | I2: Weerapong | J2: Jantarasiripas | K2: 1455601717 | L2: 1909900040261 | M2: ผู้บังคับกองร้อย | N2: ฝอ.3 พัน.ช.คมศ.พล.ช. | O2: น.3 ชั้น 24 (40,560.-บาท) | P2: โอ | Q2: กช. | R2: 898764145 | T2: กองบังคับการกองร้อย | V2: https://drive.google.com/file/d/1zPPkwGOYbgr53yUwiFdN1BUQi_5Vq1gP/view?usp=drivesdk | W2: 31021
A3: 2 | B3: 2 | C3: 2 | D3: พ.ต. | E3: นฤเบศร์ | F3: บุญคุ้ม | G3: =D3&" "&E3&" "&F3 -> พ.ต. นฤเบศร์ บุญคุ้ม | H3: MAJ | I3: Narubase | J3: Boonkoom | K3: 1520802081 | L3: 1200100337887 | M3: รองผู้บังคับกองร้อย | N3: อจ.รร.ช.กช. | O3: น.2 ชั้น 20.5 (29,110.-บาท) | P3: โอ | Q3: กช. | R3: 957966251 | T3: กองบังคับการกองร้อย | V3: https://drive.google.com/file/d/1S3CLlWHF1W2CKAhcx_aTNcsmp2bIg3Cz/view?usp=drivesdk | W3: 33296
A4: 3 | B4: 3 | C4: 3 | D4: ร.อ. | E4: พัฒนศักดิ์ | F4: บุญประเสริฐ | G4: =D4&" "&E4&" "&F4 -> ร.อ. พัฒนศักดิ์ บุญประเสริฐ | H4: CAPT | I4: Pattanasak | J4: Boonprasert | K4: 1494900475 | L4: 1700200038909 | M4: นายทหารฝ่ายกำลังพล | N4: ผช.นสบ.พล.ช. | O4: น.1 ชั้น 36.5 (28,430.-บาท) | P4: โอ | Q4: กช. | R4: 877540373 | T4: กองบังคับการกองร้อย | V4: https://drive.google.com/file/d/14QY0CtmnKGbvlyefILBbjZ0LfhpY0uib/view?usp=drivesdk | W4: 32136
A5: 4 | B5: 4 | C5: 4 | D5: พ.ต. | E5: ครรชิต | F5: โสภาสาย | G5: =D5&" "&E5&" "&F5 -> พ.ต. ครรชิต โสภาสาย | H5: MAJ | I5: Khanchit | J5: Soparsai | K5: 1495000342 | L5: 1160100207402 | M5: นายทหารฝ่ายยุทธการและการข่าว | N5: อจ.รร.ช.กช. | O5: น.2 ชั้น 21 (29,680.-บาท) | P5: บี | Q5: กช. | R5: 910568849 | T5: กองบังคับการกองร้อย | V5: https://drive.google.com/file/d/1xQe1yWUD-bFDnPCITzIy_Cyp7KB42JG9/view?usp=drivesdk | W5: 32159
A6: 5 | B6: 5 | C6: 5 | D6: ร.อ. | E6: วีรวัฒน์ | F6: เลาอารีกิจ | G6: =D6&" "&E6&" "&F6 -> ร.อ. วีรวัฒน์ เลาอารีกิจ | H6: CAPT | I6: Weerawat | J6: Lao-areekit | K6: 1482800925 | L6: 1311100021782 | M6: นายทหารฝ่ายส่งกำลังบำรุง | N6: ประจำแผนก กคช.กช. | O6: น.1 ชั้น 35.5 (27,490.-บาท) | P6: เอ | Q6: กช. | R6: 871669123 | T6: กองบังคับการกองร้อย | V6: https://drive.google.com/file/d/1PnhvQxs118ehpP1G0_bhB_DlMWv_uBru/view?usp=drivesdk | W6: 30690
A7: 6 | B7: 6 | C7: 6 | D7: ร.ท.หญิง | E7: ทิพวรรณ | F7: บุญหวา | G7: =D7&" "&E7&" "&F7 -> ร.ท.หญิง ทิพวรรณ บุญหวา | H7: 1LT | I7: Tippawan | J7: Boonwha | K7: 6491050500 | L7: 1640500026036 | M7: นายทหารฝ่ายการเงิน | N7: ประจำแผนกเงินเดือน กงด.กง.ทหาร | O7: น.1 ชั้น 36.5 (28,430.-บาท) | P7: โอ | Q7: บก.ทท. | R7: 850397199 | T7: กองบังคับการกองร้อย | V7: https://drive.google.com/file/d/11JG5ke8DEkUEWqAD2yAVAS4juVTv42-6/view?usp=drivesdk | W7: 31417
A8: 7 | B8: 7 | C8: 7 | D8: ร.ท. | E8: พัฐสรร | F8: อินนุช | G8: =D8&" "&E8&" "&F8 -> ร.ท. พัฐสรร อินนุช | H8: 1LT | I8: Patsun | J8: Innuch | K8: 1362402118 | L8: 3120100197233 | M8: นายทหารพระธรรมนูญ | N8: ประจำแผนกบังคับคดี กคด.สธน.ทบ. | O8: น.1 ชั้น 43 (35,220.- บาท) | P8: เอบี | Q8: สธน.ทบ. | R8: 923655688 | T8: กองบังคับการกองร้อย | V8: https://drive.google.com/file/d/1hzTJzc6v2Y6NIk-8LEgtLFbmmntrRqEV/view?usp=drivesdk | W8: 27498
A9: 8 | B9: 8 | C9: 8 | D9: พ.ต. | E9: คนอง | F9: คำปิว | G9: =D9&" "&E9&" "&F9 -> พ.ต. คนอง คำปิว | H9: MAJ | I9: Kanong | J9: Kampiew | K9: 1554100056 | L9: 1540300009163 | M9: อนุศาสนาจารย์ | N9: อศจ.รร.นส.ทบ. | O9: น.2 ชั้น 21.5 (30,220.- บาท) | P9: บี | Q9: ยศ.ทบ. | R9: 612935391 | T9: กองบังคับการกองร้อย | V9: https://drive.google.com/file/d/1-42ohfZpUglZ5a6Clqx5BGpGLtDMOme0/view?usp=drivesdk | W9: 31058
A10: 9 | B10: 9 | C10: 9 | D10: พ.ต. | E10: ปรัชฌา | F10: อุบลรัตน์ | G10: =D10&" "&E10&" "&F10 -> พ.ต. ปรัชฌา อุบลรัตน์ | H10: MAJ | I10: Pratcha | J10: U-bolrat | K10: 1494901694 | L10: 1709900371340 | M10: นายทหารประสานงาน | N10: ประจำแผนก ยก.ทบ. | O10: น.2 ชั้น 24 (33,000.- บาท) | P10: โอ | Q10: ยก.ทบ. | R10: 954484960 | T10: กองบังคับการกองร้อย | V10: https://drive.google.com/file/d/1gutKKSt9cx9kJ71joBV4yXOWsUNCtQ76/view?usp=drivesdk | W10: 32285
A11: 10 | B11: 10 | C11: 10 | D11: พ.ท. | E11: วิทยา | F11: ชารีรัตน์ | G11: =D11&" "&E11&" "&F11 -> พ.ท. วิทยา ชารีรัตน์ | H11: LT COL | I11: Wittaya | J11: Chareerut | K11: 1467700472 | L11: 1341800011216 | M11: นายทหารประสานงาน | N11: หน.กบ.ทบ. | O11: น.3 ชั้น 22.5 (38,500.- บาท) | P11: โอ | Q11: กบ.ทบ. | R11: 927446169 | T11: กองบังคับการกองร้อย | V11: https://drive.google.com/file/d/1idTVF8LaLoblBV3-_anBWyIBRqFsdAJd/view?usp=drivesdk | W11: 31042
A12: 11 | B12: 11 | C12: 11 | D12: ร.อ. | E12: อธิราช | F12: สีสุกงาม | G12: =D12&" "&E12&" "&F12 -> ร.อ. อธิราช สีสุกงาม | H12: CAPT | I12: Atirach | J12: Seesugngam | K12: 1432901022 | L12: 3100502031283 | M12: นายทหารประสานงาน | N12: ประจำแผนก ยก.ทบ. | O12: น.1 ชั้น 34 (26,270.- บาท) | P12: บี | Q12: ยก.ทบ. | R12: 818068599 | T12: กองบังคับการกองร้อย | V12: https://drive.google.com/file/d/1IbmDVcHv9AFDigFKjcfHw14RzC3Tcra6/view?usp=drivesdk | W12: 30063
A13: 12 | B13: 12 | C13: 12 | D13: ร.อ.หญิง | E13: เกวลี | F13: เพ็ชรแก้ว | G13: =D13&" "&E13&" "&F13 -> ร.อ.หญิง เกวลี เพ็ชรแก้ว | H13: CAPT | I13: Kewalee | J13: Phetkaew | K13: 6611050024 | L13: 1101700062902 | M13: นายทหารประสานงาน | N13: ประจำแผนกปฏิบัติการ กปก.ศสภ.ยก.ทหาร | O13: น.1 ชั้น 27.5 (21,500.- บาท) | P13: โอ | Q13: บก.ทท. | R13: 989922632 | T13: กองบังคับการกองร้อย | V13: https://drive.google.com/file/d/1NLCETsNgnR8Krsu_U2iE326IhVaqj1Dw/view?usp=drivesdk | W13: 31911
... A18: 17 | B18: 17 | C18: 101 | D18: ร.ท. | E18: ภาสวิชญ์ | F18: นิลพัฒน์ | G18: =D18&" "&E18&" "&F18 -> ร.ท. ภาสวิชญ์ นิลพัฒน์ | H18: 1LT | I18: Passawith | J18: Ninlapath | K18: 1593317578 | L18: 1103702625167 | M18: ผู้บังคับหมวด | N18: รอง ผบ.ร้อย.ช.คมศ.ที่ 2 พัน.ช.คมศ.พล.ช. | O18: น.1 ชั้น 26 (20,400.-บาท) | P18: บี | Q18: กช. | R18: 988258132 | T18: หมวดก่อสร้างทางดิ่ง | V18: https://drive.google.com/file/d/1qKytQPqcxPiE8pGPJT7WuwVraF4zw-Gb/view?usp=drivesdk | W18: 35978
A19: 18 | B19: 18 | C19: 136 | D19: ร.อ. | E19: เจษฎา | F19: ทิมฤกษ์ | G19: =D19&" "&E19&" "&F19 -> ร.อ. เจษฎา ทิมฤกษ์ | H19: CAPT | I19: Chetsada | J19: Timloek | K19: 1374900526 | L19: 3700100789372 | M19: ผู้บังคับหมวด | N19: ผบ.ร้อย.ช.ซบร.สนาม | O19: น.1 ชั้นเยียวยา 2.5 (41,930.-บาท) | P19: โอ | Q19: กช. | R19: 871611198 | T19: หมวดส่งกำลังบำรุง | U19: หมวดส่งกำลังบำรุง | V19: https://drive.google.com/file/d/1tv-8n4KyuhZpuf8f2sj44AbnamSn8yxm/view?usp=drivesdk | W19: 27746
A20: 19 | B20: 19 | C20: 137 | D20: ร.ท. | E20: สุทธิพงษ์ | F20: ทิพธามา | G20: =D20&" "&E20&" "&F20 -> ร.ท. สุทธิพงษ์ ทิพธามา | H20: 1LT | I20: Sutthiphong | J20: Thipthama | K20: 1564900809 | L20: 1709900885955 | M20: รองผู้บังคับหมวด | N20: ประจำแผนก กคช.กช. | O20: น.1 ชั้น 26.5 (20,770.-บาท) | P20: เอ | Q20: กช. | R20: 954726699 | T20: หมวดส่งกำลังบำรุง | U20: หมวดส่งกำลังบำรุง | V20: https://drive.google.com/file/d/17buBw8ZMxWPfuoe2fhw-h8vkkrrbKKUA/view?usp=drivesdk | W20: 34479
A21: 20 | B21: 20 | C21: 165 | D21: ร.ท. | E21: เอกพล | F21: เมฆประสาท | G21: =D21&" "&E21&" "&F21 -> ร.ท. เอกพล เมฆประสาท | H21: 1LT | I21: Eakkapon | J21: Makprasat | K21: 1405400448 | L21: 3331001047216 | M21: ผู้บังคับตอน | N21: ผบ.ตอน ตอนสร้างสายโถงและสายเคเบิล ร้อย.บก.พัน.ส. บก.ทท.สส.ทหาร | O21: น.1 ชั้น 45 (37,580.-บาท) | P21: เอบี | Q21: บก.ทท. | R21: 939921728 | T21: ตอนสื่อสาร | U21: หมวดส่งกำลังบำรุง | V21: https://drive.google.com/file/d/1L1t_sE6iIhJ4l8Nl_K9j5vZz3qMKHZvw/view?usp=drivesdk | W21: 28741
A22: 21 | B22: 21 | C22: 173 | D22: ร.ต. | E22: สหภาพ | F22: แววงาม | G22: =D22&" "&E22&" "&F22 -> ร.ต. สหภาพ แววงาม | H22: 2LT | I22: Sahapap | J22: Waewngam | K22: 1542402607 | L22: 1103700514015 | M22: หัวหน้าชุดเครือข่ายและดาวเทียม | N22: นายทหารโทรศัพท์ ตอนโทรศัพท์ มว.สาย ร้อย.ปสล.พัน.ส.บก.ทท.สส.ทหาร | O22: น.1 ชั้น 32.0 (24,800.-บาท) | P22: โอ | Q22: บก.ทท. | R22: 892275449 | T22: ตอนสื่อสาร | U22: หมวดส่งกำลังบำรุง | V22: https://drive.google.com/file/d/1Mkf6LJGl2QvZQY1P9Jd6w3O6xlh7xRnV/view?usp=drivesdk | W22: 33437
A23: 22 | B23: 22 | C23: 200 | D23: ร.ท. | E23: พงศ์พิทูร | F23: ศักดาชาญสวัสดิ์ | G23: =D23&" "&E23&" "&F23 -> ร.ท. พงศ์พิทูร ศักดาชาญสวัสดิ์ | H23: 1LT | I23: Pongpitoon | J23: Sakdachansawat | K23: 1581902311 | L23: 1739901727393 | M23: ผู้บังคับหมวดระวังป้องกันที่ 1 | N23: รอง ผบ.ร้อย.อวบ. ร.111 พัน.2 | O23: น.1 ชั้น 26.5 (20,770 บ.) | P23: โอ | Q23: ทภ.1 (พล.ร.11) | R23: 813636653 | T23: หมวดระวังป้องกันที่ 1 | V23: https://drive.google.com/file/d/1SKyaYnYjtJHWEDAqZx59BcoHWJPOT4zG/view?usp=drivesdk | W23: 35725
A24: 23 | B24: 23 | C24: 231 | D24: ร.ท. | E24: เกริกพงษ์ | F24: พิทักษ์สกุลหงส์ | G24: =D24&" "&E24&" "&F24 -> ร.ท. เกริกพงษ์ พิทักษ์สกุลหงส์ | H24: 1LT | I24: Krerkpong | J24: Pitaksakulhong | K24: 1570600611 | L24: 1209700676885 | M24: ผู้บังคับหมวด | N24: รอง ผบ.ร้อย.ร.ร.112 พัน.1 | O24: น.1 ชั้น 28.5 (22,230 บ.) | P24: โอ | Q24: ทภ.1 (พล.ร.11) | R24: 065-5353553 | T24: หมวดระวังป้องกันที่ 2 | V24: https://drive.google.com/file/d/1TguGhJYtACdd4IebkKvl2d78G2pFWEbK/view?usp=drivesdk | W24: 35214
A25: 24 | B25: 24 | C25: 262 | D25: ร.ท. | E25: กฤตนันท์ | F25: จันทร์อยู่ | G25: =D25&" "&E25&" "&F25 -> ร.ท. กฤตนันท์ จันทร์อยู่ | H25: 1LT | I25: Krittanan | J25: Chanyou | K25: 1653302809 | L25: 1103702509566 | M25: นายแพทย์ | N25: ผบ.มว.สร.ร้อย.บก.ร.14 พัน.3 | O25: น.1 ชั้น 28.5 (22,230.- บาท) | P25: บี | Q25: พบ. | R25: 649519419 | T25: รพ.สนามระดับ 1 | V25: https://drive.google.com/file/d/14cDtZ_81WN6xiWidSUXnmliALhn501WH/view?usp=drivesdk | W25: 35800
A26: 25 | B26: 25 | C26: 263 | D26: ร.ท. | E26: สถิรชนม์ | F26: รัตนโชคธรณี | G26: =D26&" "&E26&" "&F26 -> ร.ท. สถิรชนม์ รัตนโชคธรณี | H26: 1LT | I26: Sathirachon | J26: Ratanachokthorani | K26: 1590201769 | L26: 1710500369111 | M26: นายแพทย์ | N26: ผบ.มว.สร.ร้อย.บก.ร.152 พัน.2 | O26: น.1 ชั้น 28 (21,880.- บาท) | P26: โอ | Q26: พบ. | R26: 811975415 | T26: รพ.สนามระดับ 1 | V26: https://drive.google.com/file/d/1VRda3QoaZynuOw2yT552ymE2hO41Jfxf/view?usp=drivesdk | W26: 35965
A27: 26 | B27: 26 | C27: 264 | D27: พ.ท.หญิง | E27: วารุณี | F27: โพธา | G27: =D27&" "&E27&" "&F27 -> พ.ท.หญิง วารุณี โพธา | H27: LT COL | I27: Warunee | J27: Potha | K27: 6501013008 | L27: 1509900062357 | M27: นายทหารพยาบาล | N27: ประจำ สลก.ทบ. ชรก.กกบ.ทภ.1 | O27: น.3 ชั้น 23.5(39,880) | P27: โอ | Q27: พบ. | R27: 926699916 | T27: รพ.สนามระดับ 1 | V27: https://drive.google.com/file/d/19RQ8E8OYRZko11gCzaszZ1w_u3nIQYIy/view?usp=drivesdk | W27: 30839
A28: 27 | B28: 27 | C28: 265 | D28: ร.ท. | E28: อาคม | F28: นพกร | G28: =D28&" "&E28&" "&F28 -> ร.ท. อาคม นพกร | H28: 1LT | I28: Arkom | J28: Noppakorn | K28: 1582201589 | L28: 1809900727674 | M28: นายทหารพยาบาล | N28: พยาบาล รพ.ค่ายนวมินทราชินี | O28: น.1 ชั้น 28 (21,880.- บาท) | P28: โอ | Q28: พบ. | R28: 846905068 | T28: รพ.สนามระดับ 1 | V28: https://drive.google.com/file/d/1ggv4z6_Sl68U3jZ7HZoNqyqU7-ZmNXio/view?usp=drivesdk | W28: 34616

Sheet สำรอง
A1: ลำดับ | B1: ยศ – ชื่อ,นามสกุล | E1: fullname | F1: THAI-US ARMY RANKS | I1: หมายเลขประจำตัว | J1: หมายเลขประชาชน | K1: ตำแหน่งปกติ | L1: ชั้นเงินเดือน | M1: กลุ่มเลือด | N1: หมายเหตุ | O1: เบอร์ติดต่อ | P1: รูปภาพ | Q1: วัน เดือน ปี เกิด
A2: ส1 | B2: ร.ท.หญิง | C2: ชฎามาศ | D2: พลอยไป | E2: =B2&" "&C2&" "&D2 -> ร.ท.หญิง ชฎามาศ พลอยไป | F2: 1LT | G2: Chadamas | H2: Ploypai | I2: 6611050610 | J2: 1609900204592 | K2: ประจำ ผยก.กยก.นทพ. | L2: น.1 ชั้น 28 (21,880.- บาท) | M2: บี | N2: บก.ทท. | O2: 0644123555 | P2: https://drive.google.com/file/d/1_R1UWXDTt-bLFMDkNOWQ6egi-UL_zGKg/view?usp=drivesdk | Q2: 33649
A3: ส2 | B3: จ.ส.อ. | C3: วรินทร | D3: เปลื้องไธสง | E3: =B3&" "&C3&" "&D3 -> จ.ส.อ. วรินทร เปลื้องไธสง | F3: SM1 | G3: Warinthorn | H3: Pluengthaisong | I3: 1463313978 | J3: 1101400359942 | K3: เสมียน แผนกวิจัยและพัฒนา กฝศ.ศสภ.ทหาร | L3: ป.2 ชั้น 34 (24,800.-บาท) | M3: โอ | N3: บก.ทท. | O3: 909153399 | P3: https://drive.google.com/file/d/1muyYxcXL9vIkJFUcKEI-bb2oU_bo2hyO/view?usp=drivesdk | Q3: 31062
A4: ส3 | B4: ร.ท. | C4: พนม | D4: เพียงกระโทก | E4: =B4&" "&C4&" "&D4 -> ร.ท. พนม เพียงกระโทก | F4: 1LT | G4: Panom | H4: Piangkratok | I4: 1502100015 | J4: 1300200091072 | K4: นายทหารซ่อมบำรุงโทรโป ตอนซ่อมบำรุงโทรโป มว.โทรโปที่ 1 ร้อย.ปสพ.พัน.ส.บก.ทท.สส.ทหาร | L4: น.1 ชั้น 35 (26,990.-บาท) | M4: บี | N4: บก.ทท. | O4: 888723954 | P4: https://drive.google.com/file/d/1iTwUKaZsIZ13xdRB8wjHMfnjzZ1lGY3W/view?usp=drivesdk | Q4: 31788
A5: ส4 | B5: จ.ส.อ | C5: วชิระ | D5: งามสมฤทธิ์ | E5: =B5&" "&C5&" "&D5 -> จ.ส.อ วชิระ งามสมฤทธิ์ | F5: SM1 | G5: Wachira | H5: Ngamsomrit | I5: 1594000675 | J5: 1679800222262 | K5: หน.ชุดวิทยุปลายทาง ชุดวิทยุปลายทาง ตอนวิทยุถ่ายทอด มว.วิทยุถ่ายทอดที่ 1 ร้อย.ปสพ.พัน.ส.บก.ทท.สส.ทหาร | L5: ป.2 ชั้น 22 (17,270.-บาท) | M5: บี | N5: บก.ทท. | O5: 964895034 | P5: https://drive.google.com/file/d/1NojV82Zia51HKBajqwSxOTdAn19vqQsV/view?usp=drivesdk | Q5: 35423
A6: ส5 | B6: จ.ส.อ. | C6: รัฐพล | D6: วรรณขาม | E6: =B6&" "&C6&" "&D6 -> จ.ส.อ. รัฐพล วรรณขาม | F6: SM1 | G6: Rattapon | H6: Wannakam | I6: 1560200412 | J6: 1719900317221 | K6: หน.ชุดวิทยุถ่ายทอดกลางทาง ชุดวิทยุถ่ายทอดกลางทาง มว.วิทยุถ่ายทอดกลางทางร้อย.ปถท.พัน.ส.บก.ทท.สส.ทหาร | L6: ป.2 ชั้น 28 (20,950.-บาท) | M6: เอบี | N6: บก.ทท. | O6: 830717878 | P6: https://drive.google.com/file/d/1Kd52ZMH58RWcoU0lXcWyYQ20HiP1r-ju/view?usp=drivesdk | Q6: 34258
A7: ส6 | B7: จ.ส.อ. | C7: บุญญฤทธิ์ | D7: เรืองสูรย์ | E7: =B7&" "&C7&" "&D7 -> จ.ส.อ. บุญญฤทธิ์ เรืองสูรย์ | F7: SM1 | G7: Boonyarit | H7: Rueangsoon | I7: 1592104582 | J7: 1350100469227 | K7: หน.ชุดสร้างสาย ตอนโทรศัพท์ มว.สาย ร้อย.ปสน.พัน.ส.บก.ทท.สส.ทหาร | L7: ป.2 ชั้น 21 (16,650.-บาท) | M7: โอ | N7: บก.ทท. | O7: 922750674 | P7: https://drive.google.com/file/d/1Q204J4FVWo_wR_cCzlAX8xp6odCgNRcG/view?usp=drivesdk | Q7: 35880
A8: ส7 | B8: จ.ท.หญิง | C8: พิมพ์ชนก | D8: รังรักษ์ | E8: =B8&" "&C8&" "&D8 -> จ.ท.หญิง พิมพ์ชนก รังรักษ์ | F8: PO2 | G8: Pimchanok | H8: Rungruk | I8: 7621050219 | J8: 1100500500620 | K8: เสมียน แผนกกำลังพล กธก.ศทท.สส.ทหาร | L8: ป.1 ชั้น 22.5 (12,330.-บาท) | M8: โอ | N8: บก.ทท. | O8: 876414165 | P8: https://drive.google.com/file/d/1XjHncJHz9VLj05QpNgVnKrJj1II_pgWa/view?usp=drivesdk | Q8: 33347
A9: ส8 | B9: จ.ส.อ.หญิง | C9: สุวรรณณี | D9: ชมเชย | E9: =B9&" "&C9&" "&D9 -> จ.ส.อ.หญิง สุวรรณณี ชมเชย | F9: SM1 | G9: Suwannee | H9: Chomchoey | I9: 6591050327 | J9: 1102700773621 | K9: จนท.ประจำห้องปฏิบัติการภาพ ตอนการภาพ ร้อย.บก.พัน.ส.บก.ทท.สส.ทหาร | L9: ป.2 ชั้น 22.5 (17,570.-บาท) | M9: บี | N9: บก.ทท. | O9: 839209484 | P9: https://drive.google.com/file/d/1FTEZBhogUpykiUp65u6ujEfdYHfkIbAn/view?usp=drivesdk | Q9: 35662
A10: ส9 | B10: จ.ส.อ.หญิง | C10: อมรรัตน์ | D10: จันทร์ยิด | E10: =B10&" "&C10&" "&D10 -> จ.ส.อ.หญิง อมรรัตน์ จันทร์ยิด | F10: SM1 | G10: Amornrat | H10: Junyied | I10: 6591050618 | J10: 1710500028054 | K10: จนท.โปรแกรม แผนกโปรแกรม กพร.ศทส.สส.ทหาร | L10: ป.2 ชั้น 25 (19,100.-บาท) | M10: บี | N10: บก.ทท. | O10: 910374905 | P10: https://drive.google.com/file/d/1C0RdH7sNRFoqgMH95ye5HzbQufuk4EMz/view?usp=drivesdk | Q10: 31165
A11: ส10 | B11: จ.ส.อ.หญิง | C11: ศศินี | D11: บรรเทา | E11: =B11&" "&C11&" "&D11 -> จ.ส.อ.หญิง ศศินี บรรเทา | F11: SM1 | G11: Sasinee | H11: Banthao | I11: 6571051030 | J11: 1409800167425 | K11: จนท.ปฏิบัติการ แผนกปฏิบัติการโทรคมนาคมที่ 1 กทค.ศทท.สส.ทหาร | L11: ป.2 ชั้น 24.5 (18,790) | M11: โอ | N11: บก.ทท. | O11: 856668289 | P11: https://drive.google.com/file/d/1NAalr6eH1eCym6OX5rNpLVRd_DdnONEf/view?usp=drivesdk | Q11: 33404
A12: ส11 | B12: ส.ท. | C12: พงศกร | D12: แก่โอ๊ก | E12: =B12&" "&C12&" "&D12 -> ส.ท. พงศกร แก่โอ๊ก | F12: CPL. | G12: Phongsakon | H12: Kaeaok | I12: 1634900209 | J12: 1709901261432 | K12: นายสิบชิ้นส่วนสายช่าง | L12: ป.1 ชั้น 15 (9,150.บาท) | M12: บี | N12: กช. | O12: 953177597 | P12: https://drive.google.com/file/d/1S881QquSKBjzYgDbnXESe3N4hRaeYMTS/view?usp=drivesdk | Q12: 36262
A13: ส12 | B13: ส.อ. | C13: ธงไชย | D13: สมศรี | E13: =B13&" "&C13&" "&D13 -> ส.อ. ธงไชย สมศรี | F13: SGT | G13: Thongchai | H13: Somsri | I13: 1574901598 | J13: 1110300114076 | K13: รอง ผบ.หมู่ | L13: ป.1/ 25.5 (13,820 บาท ) | M13: บี | N13: กช. | O13: 829514390 | P13: https://drive.google.com/file/d/1JXFHvpEw4-tmuwvn-v6M0l8EdbU2_pCe/view?usp=drivesdk | Q13: 34301
A14: ส13 | B14: จ.ส.อ. | C14: สุขสรรค์ | D14: เมืองชุมพล | E14: =B14&" "&C14&" "&D14 -> จ.ส.อ. สุขสรรค์ เมืองชุมพล | F14: SM1 | G14: Suksan | H14: Mueangchumphon | I14: 1384601951 | J14: 3451000418805 | K14: จ่ากองร้อย พัน.นร.รร.ช.กช. | L14: ป.3 ชั้น 33.5 (34,680.-บาท) | M14: บี | N14: กช. | O14: 625198417 | P14: https://drive.google.com/file/d/1qAa5jtJEDT-Jb2vBfWCVlCNdX5lLjSL4/view?usp=drivesdk | Q14: 27111
... A31: ส30 | B31: พ.ต.หญิง | C31: ขนิษฐา | D31: สามารถ | E31: =B31&" "&C31&" "&D31 -> พ.ต.หญิง ขนิษฐา สามารถ | F31: MAJ | G31: Khanittha | H31: Samart | I31: 6551013030 | J31: 1100701048244 | K31: พยาบาล รพ.ค่ายนวมินทราชินี | L31: น.2 ชั้น 23 | M31: โอ | N31: พบ. | O31: 851541615 | P31: https://drive.google.com/file/d/1G7UTclihjulhwTNp3SYQgG_f0_mAlBgU/view?usp=drivesdk | Q31: 32752
A32: ส31 | B32: ร.อ. | C32: เจตนิพัทธ์ | D32: จันทร์เรือง | E32: =B32&" "&C32&" "&D32 -> ร.อ. เจตนิพัทธ์ จันทร์เรือง | F32: CAPT | G32: Jednipat | H32: Junruang | I32: 1564900728 | J32: 1101500767279 | K32: พยาบาล รพ.ค่ายนวมินทราชินี | L32: น.1 ชั้น 28 (21,880.- บาท) | M32: โอ | N32: พบ. | O32: 0901254252 | P32: https://drive.google.com/file/d/1FvS4tx17RVsndBuFwKgkQFRDKs09x5Ze/view?usp=drivesdk | Q32: 34616
A33: ส32 | B33: จ.ส.อ.หญิง | C33: วันวิสาข์ | D33: ธารวาวแวว | E33: =B33&" "&C33&" "&D33 -> จ.ส.อ.หญิง วันวิสาข์ ธารวาวแวว | F33: SM1 | G33: Wanwisa | H33: Thanwaowaeo | I33: 6551013122 | J33: 1101500591162 | K33: นายสิบพยาบาล รพ.ค่ายอดิศร | L33: ป.2 ชั้น 28 (20,950.-บาท) | M33: โอ | N33: พบ. | O33: 809654252 | P33: https://drive.google.com/file/d/1VzAEjz-aLQlzhpxvs0oEsno7ltM9moYc/view?usp=drivesdk | Q33: 33744
A34: ส33 | B34: ส.อ. | C34: ธานินทร์ | D34: เสนาะเสียง | E34: =B34&" "&C34&" "&D34 -> ส.อ. ธานินทร์ เสนาะเสียง | F34: SGT | G34: Tanin | H34: Sanaosieng | I34: 1596602959 | J34: 1329900584622 | K34: นายสิบพยาบาล ตอนรถยนต์พยาบาล มว.ส่งกลับ ร้อย.สร.สน. พัน.สร.1 | L34: ป.1 ชั้น 26 (14,060.-บาท) | M34: โอ | N34: พบ. | O34: 933964662 | P34: https://drive.google.com/file/d/1n5fORXemB5J5FnEncs8icx3GmFzFx1ys/view?usp=drivesdk | Q34: 34874
A35: ส34 | B35: ร.ท. | C35: อนุชิต | D35: บัวเลิศ | E35: =B35&" "&C35&" "&D35 -> ร.ท. อนุชิต บัวเลิศ | F35: 1LT | G35: Anuchit | H35: Bualoet | I35: 1561101291 | J35: 1869900256663 | K35: นายทหารศูนย์การสื่อสาร | L35: น.1 ชั้น 28.5 (22,230.-บาท) | M35: เอ | N35: สส. | O35: 836379994 | P35: https://drive.google.com/file/d/1RWfnKRM7Bn5CcQG7FfXx08by_iSr1-0j/view?usp=drivesdk | Q35: 34940
A36: ส35 | B36: จ.ส.อ. | C36: วิทยา | D36: เก็บกลาง | E36: =B36&" "&C36&" "&D36 -> จ.ส.อ. วิทยา เก็บกลาง | F36: SM1 | G36: Witthaya | H36: Kebklang | I36: 1462103716 | J36: 4301000001156 | K36: ช่างซ่อมวิทยุ | L36: ป.3 ชั้น 27.0 (27,960.-บาท) | M36: บี | N36: สส. | O36: 862647610 | P36: https://drive.google.com/file/d/1xIAu4UyJ1O6w60aw7keMsncNd-zODhlr/view?usp=drivesdk | Q36: 30262
A37: ส36 | B37: จ.ส.อ. | C37: สุริยา | D37: เสียงใส | E37: =B37&" "&C37&" "&D37 -> จ.ส.อ. สุริยา เสียงใส | F37: SM1 | G37: Suriya | H37: Seangsai | I37: 1534601754 | J37: 1450200168716 | K37: หน.พลนำสาร | L37: ป.2 ชั้น 30.0 (22,180.-บาท) | M37: โอ | N37: สส. | O37: 655619499 | P37: https://drive.google.com/file/d/1oB-4OmEfPe5AYcPrflolSXAYqp9CdQXg/view?usp=drivesdk | Q37: 33595
A38: ส37 | B38: จ.ส.อ. | C38: วีรวัฒน์ | D38: ศรีภูธร | E38: =B38&" "&C38&" "&D38 -> จ.ส.อ. วีรวัฒน์ ศรีภูธร | F38: SM1 | G38: Werawat | H38: Sriputorn | I38: 1505502675 | J38: 1470100182229 | K38: หน.ชุดวิทยุถ่ายทอด | L38: ป.2 ชั้น 31 (22,790.-บาท) | M38: โอ | N38: สส. | O38: 905762107 | P38: https://drive.google.com/file/d/1w0vb8LMx5s7IbMMFugZhCVBrHrKTBwBI/view?usp=drivesdk | Q38: 32561
A39: ส38 | B39: จ.ส.ท. | C39: ธีรพล | D39: นาเกลือ | E39: =B39&" "&C39&" "&D39 -> จ.ส.ท. ธีรพล นาเกลือ | F39: SM2 | G39: Teerapol | H39: Naklua | I39: 1581401719 | J39: 1929900523709 | K39: หัวหน้าช่างซ่อมและติดตั้งโทรศัพท์ | L39: ป.2 ชั้น 21.5 (16,960.-บาท) | M39: โอ | N39: สส. | O39: 889511701 | P39: https://drive.google.com/file/d/1GLzjG4g6AqPDsPkofVqYZTzLeFg4hsZR/view?usp=drivesdk | Q39: 35171
A40: ส39 | B40: ส.อ. | C40: ศตวรรษ | D40: พัตรสิงห์ | E40: =B40&" "&C40&" "&D40 -> ส.อ. ศตวรรษ พัตรสิงห์ | F40: SGT | G40: Satawat | H40: Patsing | I40: 1556603264 | J40: 1320700180406 | K40: เสมียนพิมพ์ดีด | L40: ป.1 ชั้น 29 (15,540.-บาท) | M40: โอ | N40: สส. | O40: 628515588 | P40: https://drive.google.com/file/d/1-195f-S4qUzCOjNE2ak7LmgTZZ_pzan5/view?usp=drivesdk | Q40: 33395
A41: ส40 | B41: จ.ส.อ. | C41: ศิริพรรณ | D41: ศรีอินทร์ | E41: =B41&" "&C41&" "&D41 -> จ.ส.อ. ศิริพรรณ ศรีอินทร์ | F41: SM1 | G41: Siripan | H41: Sriin | I41: 1533900914 | J41: 1709900633051 | K41: ช่างซ่อมและติดตั้งเครือข่ายภายใน | L41: ป.2 ชั้น 31 (22,790.-บาท) | M41: โอ | N41: สส. | O41: 901535389 | P41: https://drive.google.com/file/d/1Er2j-9m0pB_OxKOl7LwdUqie7mwr8SwA/view?usp=drivesdk | Q41: 33423
A42: ส41 | B42: จ.ส.อ. | C42: คมกฤช | D42: มีอยู่ | E42: =B42&" "&C42&" "&D42 -> จ.ส.อ. คมกฤช มีอยู่ | F42: SM1 | G42: Khomgrit | H42: Meeyoo | I42: 1483900748 | J42: 1769900103418 | K42: หน.ชุดวิทยุถ่ายทอด | L42: ป.2 ชั้น 35.0 (25,530.-บาท) | M42: โอ | N42: สส. | O42: 648247779 | P42: https://drive.google.com/file/d/1-uFy8xiWxRMhBeTfK938l_csSRjDSX-k/view?usp=drivesdk | Q42: 31530
A43: ส42 | B43: จ.ส.อ. | C43: ชนแดน | D43: สิงห์แก้ว | E43: =B43&" "&C43&" "&D43 -> จ.ส.อ. ชนแดน สิงห์แก้ว | F43: SM1 | G43: Chondan | H43: Singkaew | I43: 1430300381 | J43: 3461300328798 | K43: หน.พนักงานเครื่องคลื่นพาห์ | L43: ป.3 ชั้น 33 (34,110.-บาท) | M43: บี | N43: สส. | O43: 800211055 | P43: https://drive.google.com/file/d/1kYKAzpB6XQqfC4R9kCz4O0eNnUzOjhXx/view?usp=drivesdk | Q43: 28865

Sheet data
A1: ส่วนงาน | B1: ศาสนา | C1: ยอดเต็ม | D1: ทหารชาย | E1: ทหารหญิง | F1: ทบ. | G1: บก.ทท. | H1: ทหารหญิง ทบ. | I1: ทหารหญิง ทท. | K1: กองบังคับการกองร้อย | L1: หมวดก่อสร้างทางระดับที่ 1 | M1: หมวดก่อสร้างทางระดับที่ 2 | N1: หมวดก่อสร้างทางดิ่ง | O1: หมวดส่งกำลังบำรุง | P1: ตอนส่งกำลัง | Q1: ตอนซ่อมบำรุง | R1: ตอนสื่อสาร | S1: ตอนสูทกรรม | T1: ตอนยานยนต์ | U1: ตอนเครื่องมือก่อสร้าง | V1: หมวดระวังป้องกันที่ 1 | W1: หมวดระวังป้องกันที่ 2 | X1: รพ.สนามระดับ 1 | Y1: รวมนายทหาร | Z1: นายทหารชาย | AA1: นายทหารหญิง | AB1: นายสิบชาย | AC1: นายสิบหญิง | AD1: รวมนายสิบ
A2: กองบังคับการกองร้อย | B2: พุทธ | C2: =COUNTA('บรรจุ'!A2:A279) -> 273 | D2: =C2-E2 -> 245 | E2: =countif('บรรจุ'!B1:B279,"*"&"หญิง"&"*") -> 28 | F2: =C2-G2 -> 256 | G2: =COUNTIF('บรรจุ'!O1:O279,G1) -> 17 | H2: =E2-I2 -> 15 | I2: =COUNTIFS('บรรจุ'!O1:O279,G1,'บรรจุ'!B1:B279,"*"&"หญิง"&"*") -> 13 | K2: =COUNTIF(sec,K1) -> 30 | L2: =COUNTIF(sec,L1) -> 35 | M2: =COUNTIF(sec,M1) -> 35 | N2: =COUNTIF(sec,N1) -> 35 | O2: =COUNTIF(sec,O1) -> 4 | P2: =COUNTIF(sec,P1) -> 11 | Q2: =COUNTIF(sec,Q1) -> 14 | R2: =COUNTIF(sec,R1) -> 12 | ... X2: =COUNTIF(sec,X1) -> 0 | Y2: =COUNT('นายทหาร'!A2:A28) -> 27 | Z2: =Y2-AA2 -> 22 | AA2: =COUNTIF('นายทหาร'!D2:D28,"*หญิง*") -> 5 | AB2: =D2-Z2 -> 223 | AC2: =E2-AA2 -> 23 | AD2: =AB2+AC2 -> 246
A3: หมวดก่อสร้างทางระดับที่ 1 | B3: คริสต์ | C3: =COUNTA('บรรจุ'!A2:A279) -> 273 | E3: =countif('บรรจุ'!B1:B279,"*"&"หญิง"&"*") -> 28 | F3: =C3-G3 -> 256 | G3: =COUNTIF('บรรจุ'!O1:O279,G1) -> 17
A4: หมวดก่อสร้างทางระดับที่ 2 | B4: อิสลาม | C4: =COUNTA('สำรอง'!A2:A43) -> 42
A5: หมวดก่อสร้างทางดิ่ง
A6: หมวดส่งกำลังบำรุง
A7: ตอนส่งกำลัง
A8: ตอนซ่อมบำรุง
A9: ตอนสื่อสาร
A10: ตอนสูทกรรม
A11: ตอนยานยนต์
A12: ตอนเครื่องมือก่อสร้าง
A13: หมวดระวังป้องกันที่ 1
A14: หมวดระวังป้องกันที่ 2
A15: รพ.สนามระดับ 1

Sheet repatriation
A1: ลำดับ | B1: ยศ | C1: ชื่อ | D1: สกุล | E1: fullname | F1: Rank | G1: Name | H1: Lastname | I1: หมายเลขประจำตัว | J1: หมายเลขประชาชน | K1: ตำแหน่งในสนาม | L1: ตำแหน่งปกติ | M1: ชั้นเงินเดือน | N1: กลุ่มเลือด | O1: หมายเหตุ | Q1: ยศปัจจุบันเมื่อ | R1: ส่วนงาน | S1: สังกัด | T1: รูปภาพ | U1: วัน เดือน ปี เกิด | V1: ศาสนา | W1: อายุ | X1: เพศ | Y1: ประเภท | Z1: ชื่อเล่น | AA1: Line ID | AB1: Email | AC1: ผู้บังคับบัญชา | AD1: เบอร์โทร ผบช. | AE1: UN ID
A2: 201 | B2: จ.ส.อ. | C2: มนตรี | D2: รสจันทร์ | E2: =B2&" "&C2&" "&D2 -> จ.ส.อ. มนตรี รสจันทร์ | F2: SM1 | G2: Montri | H2: Roschan | I2: 1513900689 | J2: 1760500112616 | K2: รองผู้บังคับหมวด | L2: ช่างยานยนต์ล้อ ร้อย.บก.ร.111 | M2: ป.2 ชั้น 31 (22,790 บ.) | N2: โอ | O2: ทภ.1 (พล.ร.11) | P2: 988155172 | R2: หมวดระวังป้องกันที่ 1 | T2: https://drive.google.com/file/d/1GQjVheuczy095BfZ0rY44N3YWlJPoRhn/view?usp=drivesdk | U2: 32692 | V2: พุทธ | W2: =DATEDIF(U2,TODAY(),"Y") -> 37 | X2: ชาย | Y2: ประทวน | Z2: ต้อม | AE2: PKF-THAI-01329

Sheet App Metadata
A1: Last Automatic Refresh Initiated | B1: Last Manual Refresh Requested
B2: 45884.602
